Traceback (most recent call last):
  File "/home/q1063232/docker_data/docker_data_sort/vul_sort.py", line 8, in <module>
    df["updatetimestamp"] = pd.to_datetime(df["updatetimestamp"], errors="coerce")
  File "/usr/local/lib/python3.10/dist-packages/pandas/core/frame.py", line 4102, in __getitem__
    indexer = self.columns.get_loc(key)
  File "/usr/local/lib/python3.10/dist-packages/pandas/core/indexes/base.py", line 3812, in get_loc
    raise KeyError(key) from err
KeyError: 'updatetimestamp'
